Workbook
Name CopyVars: ReadMe!$A$253:$A$352
Name D: [1]REPORTS!#REF!
Name D: [2]REPORTS!#REF!
Name PROFITS: COMPETITORS!$A$85
Name QTR: COMPETITORS!$B$1
Name test: 'FIN-RPT'!$E$57:$F$60

Sheet ReadMe
A1: Welcome to the simulation!
A3: In order for this file to function properly, you will need to enable the macros.
A5: This file is divided into a number of worksheets. Here is a description of how to use this information
A6: Worksheet
A7: Name | B7: Description
B8: RESULTS OF THE SIMULATION
A9: Market Report | B9: This is a report which present marketing information for the time period that you choose to display
A10: Prod-Rpt | B10: This is a report which presents Operations information for the time period that you choose to display
A11: Fin-Rpt | B11: This is a report which present Financial informaiton for the time period that you choose to display
A12: Cash Flow | B12: This is a report which present a single period cash flow statement for the currently displayed time period
B13: At the top of each report, you can select whatever time period that you wish to display.
B15: TOOLS
A16: Tabulate | B16: This is a visual basic tool which will extract data from all time periods which contain data and display this data as a column
B17: This tool is very useful for extracting information over multiple time periods quickly for analysis or graphical display.
B19: INFORMATION
A20: Competitors | B20: This worksheet contains information about your competitors so that you can monitor them more closely.
A21: InputHistory | B21: This worksheet contains a history of all past input decisions. This information will update as each simulation cycle is executed.
A22: P0, P1 …..P75 | B22: These 32 worksheets contain raw data which represent the output or results of the simulation
B23: This data is divided into 3 sections:
C24: Rows 51 and above contain data which is public (common to all 5 teams). Columns represent COUNTRIES within these rows
C25: Rows 52 through 77 contain data which is public (common to all 5 teams). Columns represent COMPANIES within these rows
C26: Rows 78 and below contain confidential company specific data for just your company
B28: Temportary holding sheets which you should never edit
A29: ACTIVE | B29: This is a temporary holding area for data which is mapped into the 4 reports. Please do not edit this worksheet.
A30: Active -1 | B30: This is a temporary holding area for data which is mapped into the 4 reports. Please do not edit this worksheet.
A31: Data | B31: This is a temporary holding area for data which is mapped into the competitors graphs. Please do not edit this worksheet.
B33: Very Important -- Period zero output data is not real output data. It is
B34: provided only to initialize the simulation. This data should be ignored for analysis purposes
A252: CopyVar (DO NOT TOUCH)
A253: 1
A254: 2
A255: 3
A256: 4
A257: 5
A258: 6
A259: 7
A260: 8
A261: 9
A262: 10
A263: 11
...

Sheet Analysis
B2: U.S. | C2: Germany | D2: Japan
A3: R&D Expenditure | B3: 3300000 | C3: =B3/1.1 -> 3000000 | D3: =B3/1.1 -> 3000000
A5: WACC | B5: 0.126
A6: Quarterly discount rate | B6: =((1+B5)^(0.25))-1 -> 0.030112359
A7: Time Horizon (QTR) | B7: 80
A9: Plant capacity | B9: 230000
A10: Cost differential | B10: 4
A12: Annuity | B12: U.S. | C12: Germany | D12: Japan | E12: Net Benefit
A13: R&D Expenditure | B13: =B3 -> 3300000 | C13: =B13/1.1 -> 3000000 | D13: =B13/1.1 -> 3000000 | E13: =B13-C13 -> 300000
A14: Transportation | B14: 119301.75 | C14: 132099 | E14: =B14-C14 -> -12797.25
A15: Tarrifs | B15: 637964.77 | C15: 719044.29 | E15: =B15-C15 -> -81079.519
E16: =SUM(E13:E15) -> 206123.23
A19: NPV of annuity | B19: =E16*(1/B6)*(1-(1/((1+B6)^B7))) -> 6207440.4
A20: Additional Capital Costs | B20: =B9*B10 -> 920000 | E20: 5 | F20: 10 | G20: 20 | H20: BE
A21: Residual | B21: =((0.9875^B7)*B20)/((1+B6)^B7) -> 31332.018 | D21: 3.5 | E21: 1613151.5 | F21: 3249043.4 | G21: 4702267.3 | H21: 8 Quarters
A22: NPV of Capital Expenditure | B22: =B20-B21 -> 888667.98 | D22: 3 | E22: 937604.6 | F22: 2200277.7 | G22: 3333395 | H22: 11 Quarters
A23: Factory write down | B23: =(0.25)*(ACTIVE!E59) -> 2730000 | D23: 2.5 | E23: 262057.71 | F23: 1151512 | G23: 1964522.7 | H23: 16 Quarters
A24: Union buy-out | B24: 0 | D24: 2 | E24: -413489.19 | F24: 102746.25 | G24: 595650.38 | H24: 36 Quarters
A25: Total NPV | B25: =B19-SUM(B22:B24) -> 2588772.4
B30: 2000 Q4 | C30: 2001 Q1 | D30: 2001 Q2 | E30: 2001 Q3 | F30: 2001 Q4
A31: RICO
A32: Quality position | B32: 0.93944889 | C32: 1.1234076 | D32: 1.2045228 | E32: 1.0739922 | F32: 0.98107179
A33: Factory capacity | B33: 194270.45 | C33: 191842.05 | D33: 208444 | E33: 236838.45 | F33: 233877.95
A34: Net income | B34: -387137.22 | C34: -1773659.4 | D34: -1166174.7 | E34: 1078427 | F34: 28813.471
A35: Income | B35: =B34/(1-0.34) -> -586571.54 | C35: =C34/(1-0.34) -> -2687362.7 | D35: =D34/(1-0.34) -> -1766931.4 | E35: =E34/(1-0.34) -> 1633980.3 | F35: =F34/(1-0.34) -> 43656.775
A36: Debt / Equity ratio | B36: 0.25650577 | C36: 0.36859944 | D36: 0.37496164 | E36: 0.33951797 | F36: 0.34384282
A37: Cash & cash equivalents | B37: 8237696.5 | C37: 6591041.1 | D37: 1808746.4 | E37: 824634.37 | F37: 980543.84
A38: Receivables | B38: 15497217 | C38: 16732835 | D38: 20002581 | E38: 20092633 | F38: 18060233
A40: Chronologic
A41: Quality position | B41: 1.0286238 | C41: 1.1285863 | D41: 1.170918 | E41: 1.2040246 | F41: 1.2061316
A42: R&D expenditure | B42: 3 | C42: 3.5 | D42: 3.5 | E42: 3.5 | F42: 3.4
A43: Product Losses | B43: -1060903 | C43: -438885.37 | D43: -827053.51 | E43: 71287.225 | F43: 494174.69
B45: 1 | C45: =B45 -> 1 | D45: =C45 -> 1 | E45: =D45 -> 1 | F45: =E45 -> 1 | G45: =F45 -> 1 | H45: =G45 -> 1 | I45: =H45 -> 1 | J45: =I45 -> 1 | ... FC45: =FB45 -> 1
B46: -1 | C46: 0 | D46: 1 | E46: 2 | F46: 3 | G46: 4 | H46: 5 | I46: 6 | J46: 7 | K46: 8 | L46: 9 | M46: 10 | N46: 11 | O46: 12 | P46: 13 | Q46: 14 | R46: 15 | S46: 16 | T46: 17 | U46: 18 | V46: 19 | W46: 20 | X46: 21 | Y46: 22 | Z46: 23 | AA46: 24 | AB46: 25 | AC46: 26 | AD46: 27 | AE46: 28 | AF46: 29 | AG46: 30 | AH46: 31 | AI46: 32 | AJ46: 33 | AK46: 34 | AL46: 35 | AM46: 36 | AN46: 37 | AO46: 38 | AP46: 39 | AQ46: 40 | AR46: 41 | AS46: 42 | AT46: 43 | AU46: 44 | AV46: 45 | AW46: 46 | AX46: 47 | AY46: 48 | AZ46: 49 | BA46: 50 | BB46: 51 | BC46: 52 | BD46: 53 | BE46: 54 | BF46: 55 | BG46: 56 | BH46: 57 | BI46: 58 | BJ46: 59 | BK46: 60 | BL46: 61 | BM46: 62 | BN46: 63 | BO46: 64 | BP46: 65 | BQ46: 66 | BR46: 67 | BS46: 68 | BT46: 69 | BU46: 70 | BV46: 71 | BW46: 72 | BX46: 73 | BY46: 74 | BZ46: 75 | CA46: 76 | CB46: 77 | CC46: 78 | CD46: 79 | CE46: 80 | CF46: 81 | CG46: 82 | CH46: 83 | CI46: 84 | CJ46: 85 | CK46: 86 | CL46: 87 | CM46: 88 | CN46: 89 | CO46: 90 | CP46: 91 | CQ46: 92 | CR46: 93 | CS46: 94 | CT46: 95 | CU46: 96 | CV46: 97 | CW46: 98 | CX46: 99 | CY46: 100 | CZ46: 101 | DA46: 102 | DB46: 103 | DC46: 104 | DD46: 105 | DE46: 106 | DF46: 107 | DG46: 108 | DH46: 109 | DI46: 110 | DJ46: 111 | DK46: 112 | DL46: 113 | DM46: 114 | DN46: 115 | DO46: 116 | DP46: 117 | DQ46: 118 | DR46: 119 | DS46: 120 | DT46: 121 | DU46: 122 | DV46: 123 | DW46: 124 | DX46: 125 | DY46: 126 | DZ46: 127 | EA46: 128 | EB46: 129 | EC46: 130 | ED46: 131 | EE46: 132 | EF46: 133 | EG46: 134 | EH46: 135 | EI46: 136 | EJ46: 137 | EK46: 138 | EL46: 139 | EM46: 140 | EN46: 141 | EO46: 142 | EP46: 143 | EQ46: 144 | ER46: 145 | ES46: 146 | ET46: 147 | EU46: 148 | EV46: 149 | EW46: 150 | EX46: 151 | EY46: 152 | EZ46: 153 | FA46: 154 | FB46: 155 | FC46: 156
B47: 2003 Q3 | C47: 2003 Q4 | D47: 2004 Q1 | E47: 2004 Q2 | F47: 2004 Q3 | G47: 2004 Q4 | H47: 2005 Q1 | I47: 2005 Q2 | J47: 2005 Q3 | K47: 2005 Q4 | L47: 2006 Q1 | M47: 2006 Q2 | N47: 2006 Q3 | O47: 2006 Q4 | P47: 2007 Q1 | Q47: 2007 Q2 | R47: 2007 Q3 | S47: 2007 Q4 | T47: 2008 Q1 | U47: 2008 Q2 | V47: 2008 Q3 | W47: 2008 Q4 | X47: 2009 Q1 | Y47: 2009 Q2 | Z47: 2009 Q3 | AA47: 2009 Q4 | AB47: 2010 Q1 | AC47: 2010 Q2 | AD47: 2010 Q3 | AE47: 2010 Q4 | AF47: 2011 Q1 | AG47: 2011 Q2 | AH47: 2011 Q3 | AI47: 2011 Q4 | AJ47: 2012 Q1 | AK47: 2012 Q2 | AL47: 2012 Q3 | AM47: 2012 Q4 | AN47: 2013 Q1 | AO47: 2013 Q2 | AP47: 2013 Q3 | AQ47: 2013 Q4 | AR47: 2014 Q1 | AS47: 2014 Q2 | AT47: 2014 Q3 | AU47: 2014 Q4 | AV47: 2015 Q1 | AW47: 2015 Q2 | AX47: 2015 Q3 | AY47: 2015 Q4 | AZ47: 2016 Q1 | BA47: 2016 Q2 | BB47: 2016 Q3 | BC47: 2016 Q4 | BD47: 2017 Q1 | BE47: 2017 Q2 | BF47: 2017 Q3 | BG47: 2017 Q4 | BH47: 2018 Q1 | BI47: 2018 Q2 | BJ47: 2018 Q3 | BK47: 2018 Q4 | BL47: 2019 Q1 | BM47: 2019 Q2 | BN47: 2019 Q3 | BO47: 2019 Q4 | BP47: 2020 Q1 | BQ47: 2020 Q2 | BR47: 2020 Q3 | BS47: 2020 Q4 | BT47: 2021 Q1 | BU47: 2021 Q2 | BV47: 2021 Q3 | BW47: 2021 Q4 | BX47: 2022 Q1 | BY47: 2022 Q2 | BZ47: 2022 Q3 | CA47: 2022 Q4 | CB47: 2023 Q1 | CC47: 2023 Q2 | CD47: 2023 Q3 | CE47: 2023 Q4 | CF47: 2024 Q1 | CG47: 2024 Q2 | CH47: 2024 Q3 | CI47: 2024 Q4 | CJ47: 2025 Q1 | CK47: 2025 Q2 | CL47: 2025 Q3 | CM47: 2025 Q4 | CN47: 2026 Q1 | CO47: 2026 Q2 | CP47: 2026 Q3 | CQ47: 2026 Q4 | CR47: 2027 Q1 | CS47: 2027 Q2 | CT47: 2027 Q3 | CU47: 2027 Q4 | CV47: 2028 Q1 | CW47: 2028 Q2 | CX47: 2028 Q3 | CY47: 2028 Q4 | CZ47: 2029 Q1 | DA47: 2029 Q2 | DB47: 2029 Q3 | DC47: 2029 Q4 | DD47: 2030 Q1 | DE47: 2030 Q2 | DF47: 2030 Q3 | DG47: 2030 Q4 | DH47: 2031 Q1 | DI47: 2031 Q2 | DJ47: 2031 Q3 | DK47: 2031 Q4 | DL47: 2032 Q1 | DM47: 2032 Q2 | DN47: 2032 Q3 | DO47: 2032 Q4 | DP47: 2033 Q1 | DQ47: 2033 Q2 | DR47: 2033 Q3 | DS47: 2033 Q4 | DT47: 2034 Q1 | DU47: 2034 Q2 | DV47: 2034 Q3 | DW47: 2034 Q4 | DX47: 2035 Q1 | DY47: 2035 Q2 | DZ47: 2035 Q3 | EA47: 2035 Q4 | EB47: 2036 Q1 | EC47: 2036 Q2 | ED47: 2036 Q3 | EE47: 2036 Q4 | EF47: 2037 Q1 | EG47: 2037 Q2 | EH47: 2037 Q3 | EI47: 2037 Q4 | EJ47: 2038 Q1 | EK47: 2038 Q2 | EL47: 2038 Q3 | EM47: 2038 Q4 | EN47: 2039 Q1 | EO47: 2039 Q2 | EP47: 2039 Q3 | EQ47: 2039 Q4 | ER47: 2040 Q1 | ES47: 2040 Q2 | ET47: 2040 Q3 | EU47: 2040 Q4 | EV47: 2041 Q1 | EW47: 2041 Q2 | EX47: 2041 Q3 | EY47: 2041 Q4 | EZ47: 2042 Q1 | FA47: 2042 Q2 | FB47: 2042 Q3 | FC47: 2042 Q4
A48: Total Unit Cost | B48: 17.5 | C48: =B48*C45 -> 17.5 | D48: =C48*D45 -> 17.5 | E48: =D48*E45 -> 17.5 | F48: =E48*F45 -> 17.5 | G48: =F48*G45 -> 17.5 | H48: =G48*H45 -> 17.5 | I48: =H48*I45 -> 17.5 | J48: =I48*J45 -> 17.5 | ... FC48: =FB48*FC45 -> 17.5
A49: Contract advantage | B49: 6.73 | C49: 6.88 | D49: 7.021 | E49: 7.161 | F49: 7.297 | G49: 7.429 | H49: 7.557 | I49: 7.681 | J49: 7.801 | K49: 7.917 | L49: 8.029 | M49: 8.137 | N49: 8.241 | O49: 8.341 | P49: 8.437 | Q49: 8.529 | R49: 8.617 | S49: 8.701 | T49: 8.781 | U49: 8.857 | V49: 8.929 | W49: 8.997 | X49: 9.061 | Y49: 9.121 | Z49: 9.177 | AA49: 9.229 | AB49: 9.277 | AC49: 9.321 | AD49: 9.361 | AE49: 9.397 | AF49: 9.429 | AG49: 9.457 | AH49: 9.481 | AI49: 9.501 | AJ49: 9.517 | AK49: 9.529 | AL49: 9.537 | AM49: 9.54 | AN49: 9.54 | AO49: 9.54 | AP49: 9.54 | AQ49: 9.54 | AR49: 9.54 | AS49: 9.54 | AT49: 9.54 | AU49: 9.54 | AV49: 9.54 | AW49: 9.54 | AX49: 9.54 | AY49: 9.54 | AZ49: 9.54 | BA49: 9.54 | BB49: 9.54 | BC49: 9.54 | BD49: 9.54 | BE49: 9.54 | BF49: 9.54 | BG49: 9.54 | BH49: 9.54 | BI49: 9.54 | BJ49: 9.54 | BK49: 9.54 | BL49: 9.54 | BM49: 9.54 | BN49: 9.54 | BO49: 9.54 | BP49: 9.54 | BQ49: 9.54 | BR49: 9.54 | BS49: 9.54 | BT49: 9.54 | BU49: 9.54 | BV49: 9.54 | BW49: 9.54 | BX49: 9.54 | BY49: 9.54 | BZ49: 9.54 | CA49: 9.54 | CB49: 9.54 | CC49: 9.54 | CD49: 9.54 | CE49: 9.54 | CF49: 9.54 | CG49: 9.54 | CH49: 9.54 | CI49: 9.54 | CJ49: 9.54 | CK49: 9.54 | CL49: 9.54 | CM49: 9.54 | CN49: 9.54 | CO49: 9.54 | CP49: 9.54 | CQ49: 9.54 | CR49: 9.54 | CS49: 9.54 | CT49: 9.54 | CU49: 9.54 | CV49: 9.54 | CW49: 9.54 | CX49: 9.54 | CY49: 9.54 | CZ49: 9.54 | DA49: 9.54 | DB49: 9.54 | DC49: 9.54 | DD49: 9.54 | DE49: 9.54 | DF49: 9.54 | DG49: 9.54 | DH49: 9.54 | DI49: 9.54 | DJ49: 9.54 | DK49: 9.54 | DL49: 9.54 | DM49: 9.54 | DN49: 9.54 | DO49: 9.54 | DP49: 9.54 | DQ49: 9.54 | DR49: 9.54 | DS49: 9.54 | DT49: 9.54 | DU49: 9.54 | DV49: 9.54 | DW49: 9.54 | DX49: 9.54 | DY49: 9.54 | DZ49: 9.54 | EA49: 9.54 | EB49: 9.54 | EC49: 9.54 | ED49: 9.54 | EE49: 9.54 | EF49: 9.54 | EG49: 9.54 | EH49: 9.54 | EI49: 9.54 | EJ49: 9.54 | EK49: 9.54 | EL49: 9.54 | EM49: 9.54 | EN49: 9.54 | EO49: 9.54 | EP49: 9.54 | EQ49: 9.54 | ER49: 9.54 | ES49: 9.54 | ET49: 9.54 | EU49: 9.54 | EV49: 9.54 | EW49: 9.54 | EX49: 9.54 | EY49: 9.54 | EZ49: 9.54 | FA49: 9.54 | FB49: 9.54 | FC49: 9.54
A50: Effective bid | B50: 13.4 | C50: =B50 -> 13.4 | D50: =C50 -> 13.4 | E50: =D50 -> 13.4 | F50: =E50 -> 13.4 | G50: =F50 -> 13.4 | H50: =G50 -> 13.4 | I50: =H50 -> 13.4 | J50: =I50 -> 13.4 | ... FC50: =FB50 -> 13.4
A51: VC plus CA | B51: =B50+B49 -> 20.13 | C51: =C50+C49 -> 20.28 | D51: =D50+D49 -> 20.421 | E51: =E50+E49 -> 20.561 | F51: =F50+F49 -> 20.697 | G51: =G50+G49 -> 20.829 | H51: =H50+H49 -> 20.957 | I51: =I50+I49 -> 21.081 | ... FC51: =FC50+FC49 -> 22.94
A52: Profit per unit | B52: =B51-B48 -> 2.63 | C52: =C51-C48 -> 2.78 | D52: =D51-D48 -> 2.921 | E52: =E51-E48 -> 3.061 | F52: =F51-F48 -> 3.197 | G52: =G51-G48 -> 3.329 | H52: =H51-H48 -> 3.457 | I52: =I51-I48 -> 3.581 | ... FC52: =FC51-FC48 -> 5.44
...

Sheet Market Report
A1: Period Currently Displayed | C1: =ACTIVE!A2 -> 62 | F1: MARKET REPORT | K1: Select Period to View
A2: Company Number | C2: =ACTIVE!B78 -> 1
A3: Green Value of My Product 1 | C3: =ACTIVE!B273 -> 0.69763018
A4: Average Green Value of all Product 1 | C4: =ACTIVE!B275 -> 0.66862151 | F4: Product 1 Market Statistics | N4: World
B5: Japan | C5: % Wld | D5: Mexico | E5: % Wld | F5: China | G5: % Wld | H5: U.K. | I5: % Wld | J5: Germany | K5: % Wld | L5: U.S. | M5: % Wld | N5: Totals
A6: Total Demand (Units) | B6: =ACTIVE!B3 -> 373964 | C6: =B6/N6 -> 0.19655667 | D6: =ACTIVE!C3 -> 170225 | E6: =D6/N6 -> 0.089470802 | F6: =ACTIVE!D3 -> 117041 | G6: =F6/N6 -> 0.061517122 | H6: =ACTIVE!E3 -> 249421 | I6: =H6/N6 -> 0.13109647 | J6: =ACTIVE!F3 -> 272291 | K6: =J6/N6 -> 0.14311702 | L6: =ACTIVE!G3 -> 719634 | M6: =L6/N6 -> 0.37824192 | N6: =ACTIVE!H3 -> 1902576
A7: Total Sales (Units) | B7: =ACTIVE!B4 -> 373964 | C7: =B7/N7 -> 0.19655667 | D7: =ACTIVE!C4 -> 170225 | E7: =D7/N7 -> 0.089470802 | F7: =ACTIVE!D4 -> 117041 | G7: =F7/N7 -> 0.061517122 | H7: =ACTIVE!E4 -> 249421 | I7: =H7/N7 -> 0.13109647 | J7: =ACTIVE!F4 -> 272291 | K7: =J7/N7 -> 0.14311702 | L7: =ACTIVE!G4 -> 719634 | M7: =L7/N7 -> 0.37824192 | N7: =ACTIVE!H4 -> 1902576
A8: Total Marketing Exp P1 | B8: =ACTIVE!B33 -> 81400050 | C8: =(B8/ACTIVE!B49)/'Market Report'!N8 -> 0.087130819 | D8: =ACTIVE!C33 -> 3060019.2 | E8: =(D8/ACTIVE!C49)/'Market Report'!N8 -> 0.023030524 | F8: =ACTIVE!D33 -> 3360006 | G8: =(F8/ACTIVE!D49)/'Market Report'!N8 -> 0.049798508 | H8: =ACTIVE!E33 -> 889999.5 | I8: =(H8/ACTIVE!E49)/'Market Report'!N8 -> 0.13190645 | J8: =ACTIVE!F33 -> 1424999 | K8: =(J8/ACTIVE!F49)/'Market Report'!N8 -> 0.17828445 | L8: =ACTIVE!G33 -> 5500000 | M8: =L8/N8 -> 0.52984925 | N8: =ACTIVE!H33 -> 10380311
C9: Mkt sh | E9: Mkt sh | G9: Mkt sh | I9: Mkt sh | K9: Mkt sh | M9: Mkt sh
A10: Company Demand (Units) | B10: =ACTIVE!B85 -> 73793 | C10: =B10/B6 -> 0.19732648 | D10: =ACTIVE!B86 -> 30809 | E10: =D10/D6 -> 0.18098987 | F10: =ACTIVE!B87 -> 21253 | G10: =F10/F6 -> 0.18158594 | H10: =ACTIVE!B88 -> 48634 | I10: =H10/H6 -> 0.19498759 | J10: =ACTIVE!B89 -> 51834 | K10: =J10/J6 -> 0.19036252 | L10: =ACTIVE!B90 -> 156527 | M10: =L10/L6 -> 0.21750918 | N10: =SUM(ACTIVE!B85:B90) -> 382850
A11: Company Sales (Units) | B11: =ACTIVE!B91 -> 73793 | C11: =B11/B7 -> 0.19732648 | D11: =ACTIVE!B92 -> 30809 | E11: =D11/D7 -> 0.18098987 | F11: =ACTIVE!B93 -> 21253 | G11: =F11/F7 -> 0.18158594 | H11: =ACTIVE!B94 -> 48634 | I11: =H11/H7 -> 0.19498759 | J11: =ACTIVE!B95 -> 51834 | K11: =J11/J7 -> 0.19036252 | L11: =ACTIVE!B96 -> 127968 | M11: =L11/L7 -> 0.17782373 | N11: =SUM(ACTIVE!B91:B96) -> 354291
A12: Additional Sales (Units) | B12: =ACTIVE!B97 -> 0 | C12: =B12/B7 -> 0 | D12: =ACTIVE!B98 -> 0 | E12: =D12/D7 -> 0 | F12: =ACTIVE!B99 -> 0 | G12: =F12/F7 -> 0 | H12: =ACTIVE!B100 -> 0 | I12: =H12/H7 -> 0 | J12: =ACTIVE!B101 -> 0 | K12: =J12/J7 -> 0 | L12: =ACTIVE!B102 -> 0 | M12: =L12/L7 -> 0 | N12: =SUM(ACTIVE!B97:B102) -> 0
A13: Company Marketing Exp | B13: =B18 -> 14000040 | C13: =B13/B8 -> 0.17199056 | D13: =D18 -> 600000 | E13: =D13/D8 -> 0.1960772 | F13: =F18 -> 600002 | G13: =F13/F8 -> 0.1785717 | H13: =H18 -> 149999.85 | I13: =H13/H8 -> 0.16853925 | J13: =J18 -> 249999.75 | K13: =J13/J8 -> 0.17543855 | L13: =L18 -> 1000000 | M13: =L13/L8 -> 0.18181818
C14: % Sls | E14: % Sls | G14: % Sls | I14: % Sls | K14: % Sls | M14: % Sls
A15: Company Sales (currency) | B15: =ACTIVE!B103 -> 295172000 | C15: =(B15/ACTIVE!B49)/'Market Report'!N15 -> 0.20283744 | D15: =ACTIVE!B104 -> 11091240 | E15: =(D15/ACTIVE!C49)/'Market Report'!N15 -> 0.053590228 | F15: =ACTIVE!B105 -> 7226020 | G15: =(F15/ACTIVE!D49)/'Market Report'!N15 -> 0.068754522 | H15: =ACTIVE!B106 -> 1459020 | I15: =(H15/ACTIVE!E49)/'Market Report'!N15 -> 0.13882362 | J15: =ACTIVE!B107 -> 2436198 | K15: =(J15/ACTIVE!F49)/'Market Report'!N15 -> 0.19567589 | L15: =ACTIVE!B108 -> 5502624 | M15: =L15/N15 -> 0.3403183 | N15: =L15+(J15/ACTIVE!F$49)+('Market Report'!H15/ACTIVE!E$49)+('Market Report'!F15/ACTIVE!D$49)+('Market Report'!D15/ACTIVE!C$49)+('Market Report'!B15/ACTIVE!B$49) -> 16169051
A16: Delivered Mfg Cost | B16: =ACTIVE!B109*ACTIVE!B91 -> 1.2704897e+08 | C16: =B16/B15 -> 0.43042352 | D16: =ACTIVE!B110*ACTIVE!B92 -> 8017215.2 | E16: =D16/D$15 -> 0.7228421 | F16: =ACTIVE!B111*ACTIVE!B93 -> 2642695.2 | G16: =F16/F$15 -> 0.36571933 | H16: =ACTIVE!B112*ACTIVE!B94 -> 623704.65 | I16: =H16/H$15 -> 0.4274819 | J16: =ACTIVE!B113*ACTIVE!B95 -> 787464.68 | K16: =J16/J$15 -> 0.32323509 | L16: =ACTIVE!B114*ACTIVE!B96 -> 2524800.2 | M16: =L16/L$15 -> 0.45883567 | N16: =L16+(J16/ACTIVE!F$49)+('Market Report'!H16/ACTIVE!E$49)+('Market Report'!F16/ACTIVE!D$49)+('Market Report'!D16/ACTIVE!C$49)+('Market Report'!B16/ACTIVE!B$49) -> 6951595.9
A17: Gross Margin | B17: =B15-B16 -> 1.6812303e+08 | C17: =B17/B15 -> 0.56957648 | D17: =D15-D16 -> 3074024.8 | E17: =D17/D$15 -> 0.2771579 | F17: =F15-F16 -> 4583324.8 | G17: =F17/F$15 -> 0.63428067 | H17: =H15-H16 -> 835315.35 | I17: =H17/H$15 -> 0.5725181 | J17: =J15-J16 -> 1648733.3 | K17: =J17/J$15 -> 0.67676491 | L17: =L15-L16 -> 2977823.8 | M17: =L17/L$15 -> 0.54116433 | N17: =L17+(J17/ACTIVE!F$49)+('Market Report'!H17/ACTIVE!E$49)+('Market Report'!F17/ACTIVE!D$49)+('Market Report'!D17/ACTIVE!C$49)+('Market Report'!B17/ACTIVE!B$49) -> 9217455.2
A18: Company Marketing Exp | B18: =ACTIVE!B115 -> 14000040 | C18: =B18/B15 -> 0.047430109 | D18: =ACTIVE!B116 -> 600000 | E18: =D18/D$15 -> 0.054096747 | F18: =ACTIVE!B117 -> 600002 | G18: =F18/F$15 -> 0.083033537 | H18: =ACTIVE!B118 -> 149999.85 | I18: =H18/H$15 -> 0.10280863 | J18: =ACTIVE!B119 -> 249999.75 | K18: =J18/J$15 -> 0.10261881 | L18: =ACTIVE!B120 -> 1000000 | M18: =L18/L$15 -> 0.18173148 | N18: =L18+(J18/ACTIVE!F$49)+('Market Report'!H18/ACTIVE!E$49)+('Market Report'!F18/ACTIVE!D$49)+('Market Report'!D18/ACTIVE!C$49)+('Market Report'!B18/ACTIVE!B$49) -> 1850183
A19: Import Tariffs | B19: =ACTIVE!B121 -> 26565480 | C19: =B19/B15 -> 0.09 | D19: =ACTIVE!B122 -> 765295.56 | E19: =D19/D$15 -> 0.069 | F19: =ACTIVE!B123 -> 0 | G19: =F19/F$15 -> 0 | H19: =ACTIVE!B124 -> 167787.3 | I19: =H19/H$15 -> 0.115 | J19: =ACTIVE!B125 -> 280162.77 | K19: =J19/J$15 -> 0.115 | L19: =ACTIVE!B126 -> 316400.88 | M19: =L19/L$15 -> 0.0575 | N19: =L19+(J19/ACTIVE!F$49)+('Market Report'!H19/ACTIVE!E$49)+('Market Report'!F19/ACTIVE!D$49)+('Market Report'!D19/ACTIVE!C$49)+('Market Report'!B19/ACTIVE!B$49) -> 1293343.7
A20: Contribution Margin | B20: =B17-B18-B19 -> 1.2755751e+08 | C20: =B20/B15 -> 0.43214638 | D20: =D17-D18-D19 -> 1708729.2 | E20: =D20/D$15 -> 0.15406116 | F20: =F17-F18-F19 -> 3983322.8 | G20: =F20/F$15 -> 0.55124714 | H20: =H17-H18-H19 -> 517528.2 | I20: =H20/H$15 -> 0.35470946 | J20: =J17-J18-J19 -> 1118570.8 | K20: =J20/J$15 -> 0.4591461 | L20: =L17-L18-L19 -> 1661422.9 | M20: =L20/L$15 -> 0.30193285 | N20: =L20+(J20/ACTIVE!F$49)+('Market Report'!H20/ACTIVE!E$49)+('Market Report'!F20/ACTIVE!D$49)+('Market Report'!D20/ACTIVE!C$49)+('Market Report'!B20/ACTIVE!B$49) -> 6073928.6
A21: Green Value of My Product 2 | C21: =ACTIVE!B274 -> 0.63942685
A22: Average Green Value of all Product 2 | C22: =ACTIVE!B276 -> 0.64317896 | F22: Product 2 Market Statistics | N22: World
B23: Japan | C23: % Wld | D23: Mexico | E23: % Wld | F23: China | G23: % Wld | H23: U.K. | I23: % Wld | J23: Germany | K23: % Wld | L23: U.S. | M23: % Wld | N23: Totals
A24: Total Demand (Units) | B24: =ACTIVE!B8 -> 309515 | C24: =B24/N24 -> 0.16535122 | D24: =ACTIVE!C8 -> 107891 | E24: =D24/N24 -> 0.057638269 | F24: =ACTIVE!D8 -> 107891 | G24: =F24/N24 -> 0.057638269 | H24: =ACTIVE!E8 -> 256574 | I24: =H24/N24 -> 0.13706872 | J24: =ACTIVE!F8 -> 321427 | K24: =J24/N24 -> 0.17171493 | L24: =ACTIVE!G8 -> 768566 | M24: =L24/N24 -> 0.41058859 | N24: =ACTIVE!H8 -> 1871864
A25: Total Sales (Units) | B25: =ACTIVE!B9 -> 309515 | C25: =B25/N25 -> 0.16535122 | D25: =ACTIVE!C9 -> 107891 | E25: =D25/N25 -> 0.057638269 | F25: =ACTIVE!D9 -> 107891 | G25: =F25/N25 -> 0.057638269 | H25: =ACTIVE!E9 -> 256574 | I25: =H25/N25 -> 0.13706872 | J25: =ACTIVE!F9 -> 321427 | K25: =J25/N25 -> 0.17171493 | L25: =ACTIVE!G9 -> 768566 | M25: =L25/N25 -> 0.41058859 | N25: =ACTIVE!H9 -> 1871864
A26: Total Marketing Exp P2 | B26: =ACTIVE!B34 -> 83700000 | C26: =(B26/ACTIVE!B49)/'Market Report'!N26 -> 0.076795871 | D26: =ACTIVE!C34 -> 3700006.4 | E26: =(D26/ACTIVE!C49)/'Market Report'!N26 -> 0.023869726 | F26: =ACTIVE!D34 -> 3971006 | G26: =(F26/ACTIVE!D49)/'Market Report'!N26 -> 0.050447786 | H26: =ACTIVE!E34 -> 1089999.9 | I26: =(H26/ACTIVE!E49)/'Market Report'!N26 -> 0.13847394 | J26: =ACTIVE!F34 -> 1834999.3 | K26: =(J26/ACTIVE!F49)/'Market Report'!N26 -> 0.19678868 | L26: =ACTIVE!G34 -> 6220000 | M26: =L26/N26 -> 0.513624 | N26: =ACTIVE!H34 -> 12110026
C27: Mkt sh | E27: Mkt sh | G27: Mkt sh | I27: Mkt sh | K27: Mkt sh | M27: Mkt sh
A28: Company Demand (Units) | B28: =ACTIVE!B127 -> 66044 | C28: =B28/B24 -> 0.213379 | D28: =ACTIVE!B128 -> 22257 | E28: =D28/D24 -> 0.20629153 | F28: =ACTIVE!B129 -> 22786 | G28: =F28/F24 -> 0.21119463 | H28: =ACTIVE!B130 -> 56320 | I28: =H28/H24 -> 0.21950782 | J28: =ACTIVE!B131 -> 65387 | K28: =J28/J24 -> 0.20342722 | L28: =ACTIVE!B132 -> 156719 | M28: =L28/L24 -> 0.20391092 | N28: =SUM(ACTIVE!B127:B132) -> 389513
A29: Company Sales (Units) | B29: =ACTIVE!B133 -> 66044 | C29: =B29/B25 -> 0.213379 | D29: =ACTIVE!B134 -> 22257 | E29: =D29/D25 -> 0.20629153 | F29: =ACTIVE!B135 -> 22786 | G29: =F29/F25 -> 0.21119463 | H29: =ACTIVE!B136 -> 56320 | I29: =H29/H25 -> 0.21950782 | J29: =ACTIVE!B137 -> 65387 | K29: =J29/J25 -> 0.20342722 | L29: =ACTIVE!B138 -> 156719 | M29: =L29/L25 -> 0.20391092 | N29: =SUM(ACTIVE!B133:B138) -> 389513
A30: Excess Demand (Units) | B30: =ACTIVE!B139 -> 0 | C30: =B30/B25 -> 0 | D30: =ACTIVE!B140 -> 0 | E30: =D30/D25 -> 0 | F30: =ACTIVE!B141 -> 0 | G30: =F30/F25 -> 0 | H30: =ACTIVE!B142 -> 0 | I30: =H30/H25 -> 0 | J30: =ACTIVE!B143 -> 0 | K30: =J30/J25 -> 0 | L30: =ACTIVE!B144 -> 0 | M30: =L30/L25 -> 0 | N30: =SUM(ACTIVE!B139:B144) -> 0
A31: Company Marketing Exp | B31: =ACTIVE!B157 -> 17000010 | C31: =B31/B26 -> 0.20310645 | D31: =ACTIVE!B158 -> 800000 | E31: =D31/D26 -> 0.21621584 | F31: =ACTIVE!B159 -> 880002.5 | G31: =F31/F26 -> 0.22160694 | H31: =ACTIVE!B160 -> 220000.3 | I31: =H31/H26 -> 0.20183515 | J31: =ACTIVE!B161 -> 349999.65 | K31: =J31/J26 -> 0.19073557 | L31: =ACTIVE!B162 -> 1200000 | M31: =L31/L26 -> 0.19292605
C32: % Sls | E32: % Sls | G32: % Sls | I32: % Sls | K32: % Sls | M32: % Sls
A33: Company Sales (currency) | B33: =ACTIVE!B145 -> 4.028684e+08 | C33: =(B33/ACTIVE!B49)/'Market Report'!N33 -> 0.18848525 | D33: =ACTIVE!B146 -> 10015650 | E33: =(D33/ACTIVE!C49)/'Market Report'!N33 -> 0.032947756 | F33: =ACTIVE!B147 -> 10253700 | G33: =(F33/ACTIVE!D49)/'Market Report'!N33 -> 0.066423831 | H33: =ACTIVE!B148 -> 2252800 | I33: =(H33/ACTIVE!E49)/'Market Report'!N33 -> 0.14593718 | J33: =ACTIVE!B149 -> 3596285 | K33: =(J33/ACTIVE!F49)/'Market Report'!N33 -> 0.19666182 | L33: =ACTIVE!B150 -> 8776264 | M33: =L33/N33 -> 0.36954417 | N33: =L33+(J33/ACTIVE!F$49)+('Market Report'!H33/ACTIVE!E$49)+('Market Report'!F33/ACTIVE!D$49)+('Market Report'!D33/ACTIVE!C$49)+('Market Report'!B33/ACTIVE!B$49) -> 23748891
A34: Delivered Mfg Cost | B34: =ACTIVE!B151*ACTIVE!B133 -> 1.6400095e+08 | C34: =B34/B$33 -> 0.40708319 | D34: =ACTIVE!B152*ACTIVE!B134 -> 8031378 | E34: =D34/D$33 -> 0.80188286 | F34: =ACTIVE!B153*ACTIVE!B135 -> 4086504.2 | G34: =F34/F$33 -> 0.39853947 | H34: =ACTIVE!B154*ACTIVE!B136 -> 1043005.6 | I34: =H34/H$33 -> 0.46298191 | J34: =ACTIVE!B155*ACTIVE!B137 -> 1434474.4 | K34: =J34/J$33 -> 0.39887672 | L34: =ACTIVE!B156*ACTIVE!B138 -> 4418095.8 | M34: =L34/L$33 -> 0.50341418 | N34: =L34+(J34/ACTIVE!F$49)+('Market Report'!H34/ACTIVE!E$49)+('Market Report'!F34/ACTIVE!D$49)+('Market Report'!D34/ACTIVE!C$49)+('Market Report'!B34/ACTIVE!B$49) -> 10964051
A35: Gross Margin | B35: =B33-B34 -> 2.3886745e+08 | C35: =B35/B$33 -> 0.59291681 | D35: =D33-D34 -> 1984272 | E35: =D35/D$33 -> 0.19811714 | F35: =F33-F34 -> 6167195.8 | G35: =F35/F$33 -> 0.60146053 | H35: =H33-H34 -> 1209794.4 | I35: =H35/H$33 -> 0.53701809 | J35: =J33-J34 -> 2161810.6 | K35: =J35/J$33 -> 0.60112328 | L35: =L33-L34 -> 4358168.2 | M35: =L35/L$33 -> 0.49658582 | N35: =L35+(J35/ACTIVE!F$49)+('Market Report'!H35/ACTIVE!E$49)+('Market Report'!F35/ACTIVE!D$49)+('Market Report'!D35/ACTIVE!C$49)+('Market Report'!B35/ACTIVE!B$49) -> 12784840
A36: Marketing Expenses | B36: =B31 -> 17000010 | C36: =B36/B$33 -> 0.042197427 | D36: =D31 -> 800000 | E36: =D36/D$33 -> 0.079874996 | F36: =F31 -> 880002.5 | G36: =F36/F$33 -> 0.085822922 | H36: =H31 -> 220000.3 | I36: =H36/H$33 -> 0.097656383 | J36: =J31 -> 349999.65 | K36: =J36/J$33 -> 0.097322556 | L36: =L31 -> 1200000 | M36: =L36/L$33 -> 0.13673244 | N36: =L36+(J36/ACTIVE!F$49)+('Market Report'!H36/ACTIVE!E$49)+('Market Report'!F36/ACTIVE!D$49)+('Market Report'!D36/ACTIVE!C$49)+('Market Report'!B36/ACTIVE!B$49) -> 2379781
A37: Import Tariffs | B37: =ACTIVE!B163 -> 0 | C37: =B37/B$33 -> 0 | D37: =ACTIVE!B164 -> 691079.85 | E37: =D37/D$33 -> 0.069 | F37: =ACTIVE!B165 -> 943340.4 | G37: =F37/F$33 -> 0.092 | H37: =ACTIVE!B166 -> 259072 | I37: =H37/H$33 -> 0.115 | J37: =ACTIVE!B167 -> 413572.78 | K37: =J37/J$33 -> 0.115 | L37: =ACTIVE!B168 -> 504635.18 | M37: =L37/L$33 -> 0.0575 | N37: =L37+(J37/ACTIVE!F$49)+('Market Report'!H37/ACTIVE!E$49)+('Market Report'!F37/ACTIVE!D$49)+('Market Report'!D37/ACTIVE!C$49)+('Market Report'!B37/ACTIVE!B$49) -> 1639434.9
A38: Contribution Margin | B38: =B35-B36-B37 -> 2.2186744e+08 | C38: =B38/B$33 -> 0.55071938 | D38: =D35-D36-D37 -> 493192.1 | E38: =D38/D$33 -> 0.049242146 | F38: =F35-F36-F37 -> 4343852.9 | G38: =F38/F$33 -> 0.42363761 | H38: =H35-H36-H37 -> 730722.06 | I38: =H38/H$33 -> 0.32436171 | J38: =J35-J36-J37 -> 1398238.2 | K38: =J38/J$33 -> 0.38880072 | L38: =L35-L36-L37 -> 2653533.1 | M38: =L38/L$33 -> 0.30235338 | N38: =L38+(J38/ACTIVE!F$49)+('Market Report'!H38/ACTIVE!E$49)+('Market Report'!F38/ACTIVE!D$49)+('Market Report'!D38/ACTIVE!C$49)+('Market Report'!B38/ACTIVE!B$49) -> 8765624
F40: Product 1 Prices | I40: Absolute Quality of My Product 1 | L40: =ACTIVE!B271 -> 0.67340925 | N40: RELATIVE
B41: Japan | C41: rel prc | D41: Mexico | E41: rel prc | F41: China | G41: rel prc | H41: U.K. | I41: rel prc | J41: Germany | K41: rel prc | L41: U.S. | M41: rel prc | N41: QUALITY
...

Sheet PROD-RPT
A1: Period Currently Displayed | C1: =ACTIVE!A2 -> 62 | D1: PRODUCTION REPORT | I1: Select Period to View
A2: Company Number | C2: =ACTIVE!B78 -> 1
E3: PRODUCT # 1
E4: =IF(ACTIVE!B169=1,"JAPAN",IF(ACTIVE!B169=2,"MEXICO",IF(ACTIVE!B169=3,"CHINA",IF(ACTIVE!B169=4,"UNITED KINGDOM",IF(ACTIVE!B169=5,"GERMANY","UNITED STATES"))))) -> CHINA
C6: LOCAL CURRENCY | H6: RESTATED IN USD
B7: This period | C7: % Of Full | D7: This period @ | E7: Next Period @ | G7: This period | H7: This period @ | I7: Next Period @
B8: Actual | C8: Capacity | D8: Full Capacity | E8: Full Capacity | G8: Actual | H8: Full Capacity | I8: Full Capacity
A9: Production Quantity | B9: =ACTIVE!B171 -> 381774 | C9: =IF(B9=0,"",B9/D9) -> 1 | D9: =ACTIVE!B174 -> 381774 | E9: =ACTIVE!B177 -> 381834 | G9: =ACTIVE!B171 -> 381774 | H9: =ACTIVE!B174 -> 381774 | I9: =ACTIVE!B177 -> 381834
A10: Fixed Cost | B10: =ACTIVE!B172 -> 9262470.9 | C10: =IF(B10=0,"",B10/D10) -> 1 | D10: =ACTIVE!B175 -> 9262470.9 | E10: =ACTIVE!B178 -> 9186670.5 | G10: =ACTIVE!B172/(IF(ACTIVE!B$169=1,ACTIVE!B$49,IF(ACTIVE!B$169=2,ACTIVE!C$49,IF(ACTIVE!B$169=3,ACTIVE!D$49,IF(ACTIVE!B$169=4,ACTIVE!E$49,IF(ACTIVE!B$169=5,ACTIVE!F$49,ACTIVE!G$49)))))) -> 1424995.5 | H10: =ACTIVE!B175/(IF(ACTIVE!B$169=1,ACTIVE!$B$49,IF(ACTIVE!B$169=2,ACTIVE!$C$49,IF(ACTIVE!B$169=3,ACTIVE!$D$49,IF(ACTIVE!B$169=4,ACTIVE!$E$49,IF(ACTIVE!B$169=5,ACTIVE!$F$49,ACTIVE!$G$49)))))) -> 1424995.5 | I10: =ACTIVE!B178/(IF(ACTIVE!B$169=1,ACTIVE!$B$50,IF(ACTIVE!B$169=2,ACTIVE!$C$50,IF(ACTIVE!B$169=3,ACTIVE!$D$50,IF(ACTIVE!B$169=4,ACTIVE!$E$50,IF(ACTIVE!B$169=5,ACTIVE!$F$50,ACTIVE!$G$50)))))) -> 1506011.5
A11: Variable Cost | B11: =ACTIVE!B173 -> 35058253 | C11: =IF(B11=0,"",B11/D11) -> 1 | D11: =ACTIVE!B176 -> 35058253 | E11: =ACTIVE!B179 -> 34821776 | G11: =ACTIVE!B173/(IF(ACTIVE!B$169=1,ACTIVE!B$49,IF(ACTIVE!B$169=2,ACTIVE!C$49,IF(ACTIVE!B$169=3,ACTIVE!D$49,IF(ACTIVE!B$169=4,ACTIVE!E$49,IF(ACTIVE!B$169=5,ACTIVE!F$49,ACTIVE!G$49)))))) -> 5393577.3 | H11: =ACTIVE!B176/(IF(ACTIVE!B$169=1,ACTIVE!$B$49,IF(ACTIVE!B$169=2,ACTIVE!$C$49,IF(ACTIVE!B$169=3,ACTIVE!$D$49,IF(ACTIVE!B$169=4,ACTIVE!$E$49,IF(ACTIVE!B$169=5,ACTIVE!$F$49,ACTIVE!$G$49)))))) -> 5393577.3 | I11: =ACTIVE!B179/(IF(ACTIVE!B$169=1,ACTIVE!$B$50,IF(ACTIVE!B$169=2,ACTIVE!$C$50,IF(ACTIVE!B$169=3,ACTIVE!$D$50,IF(ACTIVE!B$169=4,ACTIVE!$E$50,IF(ACTIVE!B$169=5,ACTIVE!$F$50,ACTIVE!$G$50)))))) -> 5708487.9
A12: Total Cost | B12: =B10+B11 -> 44320724 | C12: =IF(B12=0,"",B12/D12) -> 1 | D12: =D10+D11 -> 44320724 | E12: =E11+E10 -> 44008447 | G12: =G10+G11 -> 6818572.8 | H12: =H10+H11 -> 6818572.8 | I12: =I10+I11 -> 7214499.5
A13: Variable Cost per unit | B13: =IF(B11=0,0,B11/B9) -> 91.829859 | C13: =IF(B13=0,"",B13/D13) -> 1 | D13: =IF(D11=0,0,D11/D9) -> 91.829859 | E13: =IF(E11=0,0,E11/E9) -> 91.196112 | G13: =IF(G11=0,0,G11/G9) -> 14.127671 | H13: =IF(H11=0,0,H11/H9) -> 14.127671 | I13: =IF(I11=0,0,I11/I9) -> 14.950182
A14: Total Cost per unit | B14: =IF(B12=0,0,B12/B9) -> 116.09152 | C14: =IF(B14=0,"",B14/D14) -> 1 | D14: =IF(D12=0,0,D12/D9) -> 116.09152 | E14: =IF(E12=0,0,E12/E9) -> 115.25544 | G14: =IF(G12=0,0,G12/G9) -> 17.860234 | H14: =IF(H12=0,0,H12/H9) -> 17.860234 | I14: =IF(I12=0,0,I12/I9) -> 18.894335
D16: INVENTORY PRODUCT 1
A17: Inventory is valued | B17: Inventory | D17: Inventory | E17: Inventory | F17: Total | G17: Months of | H17: Maximum Possible construction
A18: in local currency | B18: Produced | D18: Produced | E18: Purchased | F18: Inventory | G18: Sales | H18: Next Time Period - Product 1
B19: Previously | D19: This period | E19: This period | H19: Max Units | I19: =0.15*I9 -> 57275.1
A20: UNITS | B20: =ACTIVE!B189 -> 0 | D20: =ACTIVE!B192 -> 0 | E20: =ACTIVE!B195 -> 38285 | F20: =B20+D20+E20 -> 38285 | G20: =3*F20/SUM(ACTIVE!B91:B102) -> 0.32418266 | H20: Max Dollars | I20: =ACTIVE!B268 -> 916401.6
A21: VALUE | B21: =ACTIVE!B190 -> 0 | D21: =ACTIVE!B193 -> 0 | E21: =ACTIVE!B196 -> 5191121 | F21: =B21+D21+E21 -> 5191121
A22: COST / UNIT | B22: =ACTIVE!B191 -> 0 | D22: =ACTIVE!B194 -> 0 | E22: =ACTIVE!B197 -> 135.59152 | F22: =F21/F20 -> 135.59151
E24: PRODUCT # 2
E25: =IF(ACTIVE!B170=1,"JAPAN",IF(ACTIVE!B170=2,"MEXICO",IF(ACTIVE!B170=3,"CHINA",IF(ACTIVE!B170=4,"UNITED KINGDOM",IF(ACTIVE!B170=5,"GERMANY","UNITED STATES"))))) -> JAPAN
C27: LOCAL CURRENCY | H27: RESTATED IN USD
B28: This period | C28: % Of Full | D28: This period @ | E28: Next Period @ | G28: This period | H28: This period @ | I28: Next Period @
A29: PRODUCT # 2 | B29: Actual | C29: Capacity | D29: Full Capacity | E29: Full Capacity | G29: Actual | H29: Full Capacity | I29: Full Capacity
A30: Production Quantity | B30: =ACTIVE!B180 -> 365570 | C30: =IF(B30=0,"",B30/D30) -> 1 | D30: =ACTIVE!B183 -> 365570 | E30: =ACTIVE!B186 -> 364656 | G30: =ACTIVE!B180 -> 365570 | H30: =ACTIVE!B183 -> 365570 | I30: =ACTIVE!B186 -> 364656
A31: Fixed Cost | B31: =ACTIVE!B181 -> 214154470 | C31: =IF(B31=0,"",B31/D31) -> 1 | D31: =ACTIVE!B184 -> 214154470 | E31: =ACTIVE!B187 -> 2.1383576e+08 | G31: =ACTIVE!B181/(IF(ACTIVE!$B$170=1,ACTIVE!$B$49,IF(ACTIVE!$B$170=2,ACTIVE!$C$49,IF(ACTIVE!$B$170=3,ACTIVE!$D$49,IF(ACTIVE!$B$170=4,ACTIVE!$E$49,IF(ACTIVE!$B$170=5,ACTIVE!$F$49,ACTIVE!$G$49)))))) -> 2379494.1 | H31: =ACTIVE!$B184/(IF(ACTIVE!$B$170=1,ACTIVE!$B$49,IF(ACTIVE!$B$170=2,ACTIVE!$C$49,IF(ACTIVE!$B$170=3,ACTIVE!$D$49,IF(ACTIVE!$B$170=4,ACTIVE!$E$49,IF(ACTIVE!$B$170=5,ACTIVE!$F$49,ACTIVE!$G$49)))))) -> 2379494.1 | I31: =ACTIVE!$B187/(IF(ACTIVE!$B$170=1,ACTIVE!$B$50,IF(ACTIVE!$B$170=2,ACTIVE!$C$50,IF(ACTIVE!$B$170=3,ACTIVE!$D$50,IF(ACTIVE!$B$170=4,ACTIVE!$E$50,IF(ACTIVE!$B$170=5,ACTIVE!$F$50,ACTIVE!$G$50)))))) -> 2375952.9
A32: Variable Cost | B32: =ACTIVE!B182 -> 650645803 | C32: =IF(B32=0,"",B32/D32) -> 1 | D32: =ACTIVE!B185 -> 650645803 | E32: =ACTIVE!B188 -> 652737820 | G32: =ACTIVE!B182/(IF(ACTIVE!$B$170=1,ACTIVE!B$49,IF(ACTIVE!$B$170=2,ACTIVE!C$49,IF(ACTIVE!$B$170=3,ACTIVE!D$49,IF(ACTIVE!$B$170=4,ACTIVE!E$49,IF(ACTIVE!$B$170=5,ACTIVE!F$49,ACTIVE!G$49)))))) -> 7229397.8 | H32: =ACTIVE!$B185/(IF(ACTIVE!$B$170=1,ACTIVE!$B$49,IF(ACTIVE!$B$170=2,ACTIVE!$C$49,IF(ACTIVE!$B$170=3,ACTIVE!$D$49,IF(ACTIVE!$B$170=4,ACTIVE!$E$49,IF(ACTIVE!$B$170=5,ACTIVE!$F$49,ACTIVE!$G$49)))))) -> 7229397.8 | I32: =ACTIVE!$B188/(IF(ACTIVE!$B$170=1,ACTIVE!$B$50,IF(ACTIVE!$B$170=2,ACTIVE!$C$50,IF(ACTIVE!$B$170=3,ACTIVE!$D$50,IF(ACTIVE!$B$170=4,ACTIVE!$E$50,IF(ACTIVE!$B$170=5,ACTIVE!$F$50,ACTIVE!$G$50)))))) -> 7252642.4
A33: Total Cost | B33: =B32+B31 -> 864800273 | C33: =IF(B33=0,"",B33/D33) -> 1 | D33: =D31+D32 -> 864800273 | E33: =E31+E32 -> 8.6657358e+08 | G33: =G31+G32 -> 9608891.9 | H33: =H31+H32 -> 9608891.9 | I33: =I31+I32 -> 9628595.3
A34: Variable Cost per unit | B34: =IF(B32=0,0,B32/B30) -> 1779.8118 | C34: =IF(B34=0,"",B34/D34) -> 1 | D34: =IF(D32=0,0,D32/D30) -> 1779.8118 | E34: =IF(E32=0,0,E32/E30) -> 1790.0098 | G34: =IF(G32=0,0,G32/G30) -> 19.775687 | H34: =IF(H32=0,0,H32/H30) -> 19.775687 | I34: =IF(I32=0,0,I32/I30) -> 19.888998
A35: Total Cost per unit | B35: =IF(B33=0,0,B33/B30) -> 2365.6216 | C35: =IF(B35=0,"",B35/D35) -> 1 | D35: =IF(D33=0,0,D33/D30) -> 2365.6216 | E35: =IF(E33=0,0,E33/E30) -> 2376.4139 | G35: =IF(G33=0,0,G33/G30) -> 26.284684 | H35: =IF(H33=0,0,H33/H30) -> 26.284684 | I35: =IF(I33=0,0,I33/I30) -> 26.404599
D37: INVENTORY PRODUCT 2
A38: Inventory is valued | B38: Inventory | D38: Inventory | E38: Inventory | F38: Total | G38: Months of | H38: Maximum Possible construction
A39: in local currency | B39: Produced | D39: Produced | E39: Purchased | F39: Inventory | G39: Sales | H39: Next Time Period - Product 2
B40: Previously | D40: This period | E40: This period | H40: Max Units | I40: =0.15*I30 -> 54698.4
A41: UNITS | B41: =ACTIVE!B198 -> 0 | D41: =ACTIVE!B201 -> 30349 | E41: =ACTIVE!B204 -> 8602 | F41: =B41+D41+E41 -> 38951 | G41: =3*F41/SUM(ACTIVE!B133:B138) -> 0.29999769 | H41: Max Dollars | I41: =ACTIVE!B269 -> 1367460
A42: VALUE | B42: =ACTIVE!B199 -> 0 | D42: =ACTIVE!B202 -> 71794260 | E42: =ACTIVE!B205 -> 22671630 | F42: =B42+D42+E42 -> 94465890
A43: COST / UNIT | B43: =ACTIVE!B200 -> 0 | D43: =ACTIVE!B203 -> 2365.6216 | E43: =ACTIVE!B206 -> 2635.6216
B45: TRANSPORTATION REPORT
F46: USD | H46: FACTORY RELOCATION ACTIVITY
...

Sheet FIN-RPT
A1: Period Currently Displayed | C1: =ACTIVE!A2 -> 62 | G1: FINANCE REPORT | L1: Select Period to View
A2: Company Number | C2: =ACTIVE!B78 -> 1
A3: PERIOD NUMBER | B3: =ACTIVE!A2 -> 62 | F3: BALANCE SHEET DATA
B4: Company 1 | C4: % | D4: Company 2 | E4: % | F4: Company 3 | G4: % | H4: Company 4 | I4: % | J4: Company 5 | K4: % | N4: DETAILED INCOME STATEMENT
A5: Cash and Securities | B5: =ACTIVE!B52 -> 17058310 | C5: =B5/B$10 -> 0.33309835 | D5: =ACTIVE!C52 -> 14337599 | E5: =D5/D$10 -> 0.30051949 | F5: =ACTIVE!D52 -> 13181975 | G5: =F5/F$10 -> 0.26912181 | H5: =ACTIVE!E52 -> 15953846 | I5: =H5/H$10 -> 0.26559683 | J5: =ACTIVE!F52 -> 18473814 | K5: =IF(J$10=0,0,J5/J$10) -> 0.29581649 | N5: Sales Revenues | Q5: {=ACTIVE!$B$213:$B$216} -> 42718742 | R5: =Q5/Q$8 -> 0.99469619
A6: Receivables | B6: =ACTIVE!B53 -> 13839266 | C6: =B6/B$10 -> 0.27023994 | D6: =ACTIVE!C53 -> 13815783 | E6: =D6/D$10 -> 0.2895821 | F6: =ACTIVE!D53 -> 13068165 | G6: =F6/F$10 -> 0.26679827 | H6: =ACTIVE!E53 -> 16279448 | I6: =H6/H$10 -> 0.27101739 | J6: =ACTIVE!F53 -> 22480549 | K6: =IF(J$10=0,0,J6/J$10) -> 0.35997532 | N6: Interest Income | Q6: 227780 | R6: =Q6/Q$8 -> 0.0053038055
A7: Inventories | B7: =ACTIVE!B54+ACTIVE!B55 -> 1848255 | C7: =B7/B$10 -> 0.036090955 | D7: =ACTIVE!C54+ACTIVE!C55 -> 2955165 | E7: =D7/D$10 -> 0.061940962 | F7: =ACTIVE!D56 -> 6322030 | G7: =F7/F$10 -> 0.1290699 | H7: =ACTIVE!E56 -> 5408304 | I7: =H7/H$10 -> 0.090036495 | J7: =ACTIVE!F56 -> 2244069 | K7: =IF(J$10=0,0,J7/J$10) -> 0.035933707 | N7: Currency Trading Income | Q7: 0 | R7: =Q7/Q$8 -> 0
A8: Shipping Cont (Net) | B8: =ACTIVE!B57 -> 3239458 | C8: =B8/B$10 -> 0.063257035 | D8: =ACTIVE!C57 -> 3439038 | E8: =D8/D$10 -> 0.072083055 | F8: =ACTIVE!D57 -> 3247478 | G8: =F8/F$10 -> 0.066300167 | H8: =ACTIVE!E57 -> 3502596 | I8: =H8/H$10 -> 0.058310603 | J8: =ACTIVE!F57 -> 3256316 | K8: =IF(J$10=0,0,J8/J$10) -> 0.052142561 | N8: TOTAL REVENUES | Q8: 42946522 | R8: =Q8/Q$8 -> 1
A9: Plant and Equip (Net) | B9: =ACTIVE!B58+ACTIVE!B59 -> 15225742 | C9: =B9/B$10 -> 0.29731372 | D9: =ACTIVE!C60 -> 13161797 | E9: =D9/D$10 -> 0.2758744 | F9: =ACTIVE!D60 -> 13161797 | G9: =F9/F$10 -> 0.26870986 | H9: =ACTIVE!E60 -> 18923715 | I9: =H9/H$10 -> 0.31503868 | J9: =ACTIVE!F60 -> 15995503 | K9: =IF(J$10=0,0,J9/J$10) -> 0.25613193
A10: TOTAL ASSETS | B10: =ACTIVE!B61 -> 51211031 | D10: =ACTIVE!C61 -> 47709382 | F10: =ACTIVE!D61 -> 48981445 | G10: =F10/F$10 -> 1 | H10: =ACTIVE!E61 -> 60067909 | J10: =ACTIVE!F61 -> 62450251 | N10: Cost of goods sold | Q10: =ACTIVE!B217 -> 19859535 | R10: =Q10/Q$8 -> 0.46242476
N11: Gross Margin | Q11: =Q8-Q10 -> 23086987 | R11: =Q11/Q$8 -> 0.53757524
A12: Trade Payables | B12: {=ACTIVE!$B$62:$B$67} -> 8213732.4 | C12: =B12/B$17 -> 0.1603899 | D12: {=ACTIVE!$C$62:$C$67} -> 8029973.4 | E12: =D12/D$17 -> 0.16831015 | F12: {=ACTIVE!$D$62:$D$67} -> 8029973.4 | G12: =F12/F$17 -> 0.16393909 | H12: {=ACTIVE!$E$62:$E$67} -> 9294741.4 | I12: =H12/H$17 -> 0.15473722 | J12: {=ACTIVE!$F$62:$F$67} -> 7750000.2 | K12: =IF(J$17=0,0,J12/J$17) -> 0.12409878 | N12: OPERATING EXPENSES
A13: Taxes Payable | B13: 782650 | C13: =B13/B$17 -> 0.01528284 | D13: 794437 | E13: =D13/D$17 -> 0.016651589 | F13: 1113469 | G13: =F13/F$17 -> 0.022732465 | H13: -177067 | I13: =H13/H$17 -> -0.0029477803 | J13: 1521924 | K13: =IF(J$17=0,0,J13/J$17) -> 0.024370182 | N13: Transportation Expenses | Q13: {=ACTIVE!$B$218:$B$231} -> 1325997.7 | R13: =Q13/Q$8 -> 0.030875555
A14: Loans and Interest | B14: 22283217 | C14: =B14/B$17 -> 0.43512533 | D14: 21248394 | E14: =D14/D$17 -> 0.4453714 | F14: 23318568 | G14: =F14/F$17 -> 0.47606942 | H14: 32664757 | I14: =H14/H$17 -> 0.54379713 | J14: 32122418 | K14: =IF(J$17=0,0,J14/J$17) -> 0.51436812 | N14: Marketing Expenses | Q14: 4229964 | R14: =Q14/Q$8 -> 0.098493751
A15: Common Stock | B15: 1000000 | C15: =B15/B$17 -> 0.019527043 | D15: 1000000 | E15: =D15/D$17 -> 0.020960238 | F15: 1000000 | G15: =F15/F$17 -> 0.020415894 | H15: 1000000 | I15: =H15/H$17 -> 0.016647824 | J15: 1000000 | K15: =IF(J$17=0,0,J15/J$17) -> 0.016012746 | N15: Warehousing Expenses | Q15: 177236 | R15: =Q15/Q$8 -> 0.0041269
A16: Retained Earnings | B16: 18931432 | C16: =B16/B$17 -> 0.36967488 | D16: 16636578 | E16: =D16/D$17 -> 0.34870662 | F16: 15519435 | G16: =F16/F$17 -> 0.31684313 | H16: 17285478 | I16: =H16/H$17 -> 0.2877656 | J16: 20055909 | K16: =IF(J$17=0,0,J16/J$17) -> 0.32115017 | N16: Research & Development | Q16: 6240000 | R16: =Q16/Q$8 -> 0.14529698
A17: TOTAL LIAB & EQUITY | B17: 51211031 | D17: 47709382 | F17: 48981445 | H17: 60067909 | J17: 62450251 | N17: Interest Expense | Q17: 815763 | R17: =Q17/Q$8 -> 0.018994856
A18: Debt/Equity | B18: =B14/(B15+B16) -> 1.1179938 | D18: =D14/(D15+D16) -> 1.2047912 | F18: =F14/(F15+F16) -> 1.4115839 | H18: =H14/(H15+H16) -> 1.786377 | J18: =J14/(J15+J16) -> 1.5255774 | N18: Factory Depreciation | Q18: 190596 | R18: =Q18/Q$8 -> 0.0044379846
A19: DIVIDENDS PAID | B19: =ACTIVE!B68 -> 0 | D19: =ACTIVE!C68 -> 0 | F19: =ACTIVE!D68 -> 0 | H19: =ACTIVE!E68 -> 0 | J19: =ACTIVE!F68 -> 0 | N19: Factory Sale Loss | Q19: 1083003.6 | R19: =Q19/Q$8 -> 0.025217493
N20: Inventory Write Down | Q20: 0 | R20: =Q20/Q$8 -> 0
F21: INCOME STATEMENT DATA | N21: Consultants | Q21: 3191000 | R21: =Q21/Q$8 -> 0.07430171
B22: Company 1 | C22: % | D22: Company 2 | E22: % | F22: Company 3 | G22: % | H22: Company 4 | I22: % | J22: Company 5 | K22: % | N22: Insurance | Q22: 160000 | R22: =Q22/Q$8 -> 0.0037255636
A23: Total Sales Revenue | B23: =ACTIVE!B69 -> 42718742 | D23: =ACTIVE!C69 -> 40004345 | F23: =ACTIVE!D69 -> 36246031 | H23: =ACTIVE!E69 -> 39253391 | J23: =ACTIVE!F69 -> 41113091 | N23: Admin and Misc Expenses | Q23: 169775.04 | R23: =Q23/Q$8 -> 0.0039531731
A24: Net Income | B24: =ACTIVE!B70 -> 1519262.8 | C24: =B24/B23 -> 0.035564316 | D24: =ACTIVE!C70 -> 1542141.5 | E24: =D24/D23 -> 0.03854935 | F24: =ACTIVE!D70 -> 2161438.7 | G24: =F24/F23 -> 0.059632424 | H24: =ACTIVE!E70 -> -343721.6 | I24: =H24/H23 -> -0.0087564815 | J24: =ACTIVE!F70 -> 2954323.4 | K24: =IF(J23=0,0,J24/J23) -> 0.07185846 | N24: Bad Debt Expenses | Q24: 268960 | R24: =Q24/Q$8 -> 0.0062626725
A25: Annualized ROE | B25: =4*B24/SUM(B15:B16) -> 0.30489789 | D25: =4*D24/SUM(D15:D16) -> 0.34975981 | F25: =4*F24/SUM(F15:F16) -> 0.52336868 | H25: =4*H24/SUM(H15:H16) -> -0.075190071 | J25: =IF(SUM(J23:J24)=0,0,4*J24/SUM(J15:J16)) -> 0.56123408 | N25: Import Tariffs | Q25: 2932778.5 | R25: =Q25/Q$8 -> 0.068289082
N26: TOTAL OPERATING EXP | Q26: 40644609 | R26: =Q26/Q$8 -> 0.94640048
A27: From -->>> | F27: TARIFF RATES
A28: To | B28: Japan | D28: Mexico | F28: China | H28: U.K. | J28: Germany | L28: U.S. | N28: PRETAX INCOME | Q28: {=ACTIVE!$B$232:$B$234} -> 2301912.8 | R28: =Q28/Q$8 -> 0.053599518
A29: Japan | B29: {=ACTIVE!$B$35:$B$40} -> 0 | D29: {=ACTIVE!$C$35:$C$40} -> 0.09 | F29: {=ACTIVE!$D$35:$D$40} -> 0.09 | H29: {=ACTIVE!$E$35:$E$40} -> 0.09 | J29: {=ACTIVE!$F$35:$F$40} -> 0.09 | L29: {=ACTIVE!$G$35:$G$40} -> 0.09 | N29: TAXES | Q29: 782650 | R29: =Q29/Q$8 -> 0.018223827
A30: Mexico | B30: 0.069 | D30: 0 | F30: 0.069 | H30: 0.069 | J30: 0.069 | L30: 0 | N30: NET INCOME | Q30: 1519262.8 | R30: =Q30/Q$8 -> 0.03537569
A31: China | B31: 0.092 | D31: 0.092 | F31: 0 | H31: 0.092 | J31: 0.092 | L31: 0.092
A32: U.K. | B32: 0.115 | D32: 0.115 | F32: 0.115 | H32: 0 | J32: 0 | L32: 0.115
A33: Germany | B33: 0.115 | D33: 0.115 | F33: 0.115 | H33: 0 | J33: 0 | L33: 0.115 | Q33: INSURANCE SUMMARY
A34: U.S. | B34: 0.0575 | D34: 0 | F34: 0.0575 | H34: 0.0575 | J34: 0.0575 | L34: 0 | N34: Rates are USD per 100,000 coverage per QTR.
Q35: Rate | R35: Coverage $ | S35: Premium $
A36: From -->>> | F36: TRANSPORT RATES | O36: Property / Casualty | Q36: =ACTIVE!B238 -> 400 | R36: =ACTIVE!B235 -> 6250000 | S36: =(R36/100000)*Q36 -> 25000
A37: To | B37: Japan | D37: Mexico | F37: China | H37: U.K. | J37: Germany | L37: U.S. | O37: Directors & Officers | Q37: =ACTIVE!B239 -> 300 | R37: =ACTIVE!B236 -> 11666667 | S37: =(R37/100000)*Q37 -> 35000
A38: Japan | B38: {=ACTIVE!$B$41:$B$46} -> 0.6 | D38: {=ACTIVE!$C$41:$C$46} -> 1.2 | F38: {=ACTIVE!$D$41:$D$46} -> 0.6 | H38: {=ACTIVE!$E$41:$E$46} -> 1.5 | J38: {=ACTIVE!$F$41:$F$46} -> 1.5 | L38: {=ACTIVE!$G$41:$G$46} -> 1.2 | O38: Product Liability | Q38: =ACTIVE!B240 -> 1000 | R38: =ACTIVE!B237 -> 10000000 | S38: =(R38/100000)*Q38 -> 100000
A39: Mexico | B39: 1.2 | D39: 0.6 | F39: 1.8 | H39: 1.2 | J39: 1.2 | L39: 0.6
A40: China | B40: 0.6 | D40: 1.8 | F40: 0.6 | H40: 1.2 | J40: 1.2 | L40: 1.2
...

Sheet Cash Flow
A1: Select Period to View Period Currently Displayed | B1: =ACTIVE!A2 -> 62 | C1: CASH FLOW
A2: Company Number | B2: =ACTIVE!B78 -> 1 | C2: Report
H3: How Well Are You Managing Your Capital And Your Assets?
A4: CASH FLOWS FROM OPERATING ACTIVITIES | F4: Period 1 | G4: Period 2 | H4: Period 3 | I4: Period 4 | J4: Period 5 | K4: Period 6 | L4: Period 7 | M4: Period 8 | N4: Period 9 | O4: Period 10 | P4: Period 11 | Q4: Period 12 | R4: Period 13 | S4: Period 14 | T4: Period 15 | U4: Period 16 | V4: Period 17 | W4: Period 18 | X4: Period 19 | Y4: Period 20 | Z4: Period 21 | AA4: Period 22 | AB4: Period 23 | AC4: Period 24 | AD4: Period 25 | AE4: Period 26 | AF4: Period 27 | AG4: Period 28 | AH4: Period 29 | AI4: Period 30 | AJ4: Period 31 | AK4: Period 32 | AL4: Period 33 | AM4: Period 34 | AN4: Period 35 | AO4: Period 36 | AP4: Period 37 | AQ4: Period 38 | AR4: Period 39 | AS4: Period 40 | AT4: Period 41 | AU4: Period 42 | AV4: Period 43 | AW4: Period 44 | AX4: Period 45 | AY4: Period 46 | AZ4: Period 47 | BA4: Period 48 | BB4: Period 49 | BC4: Period 50 | BD4: Period 51 | BE4: Period 52 | BF4: Period 53 | BG4: Period 54 | BH4: Period 55 | BI4: Period 56 | BJ4: Period 57 | BK4: Period 58 | BL4: Period 59 | BM4: Period 60 | BN4: Period 61 | BO4: Period 62 | BP4: Period 63 | BQ4: Period 64 | BR4: Period 65 | BS4: Period 66 | BT4: Period 67 | BU4: Period 68 | BV4: Period 69 | BW4: Period 70 | BX4: Period 71 | BY4: Period 72 | BZ4: Period 73 | CA4: Period 74 | CB4: Period 75
A5: Net profits | C5: =ACTIVE!B70 -> 1519262.8 | E5: Net Operating Profit After Tax | F5: ='P1'!$B277 -> 4228837.3 | G5: ='P2'!$B277 -> 3384229 | H5: ='P3'!$B277 -> 2912688.1 | I5: ='P4'!$B277 -> 3877406.6 | J5: ='P5'!$B277 -> 4054908.5 | K5: ='P6'!$B277 -> 1546967.6 | L5: ='P7'!$B277 -> 661402.46 | M5: ='P8'!$B277 -> 3284959.9 | N5: ='P9'!$B277 -> 1739084.6 | O5: ='P10'!$B277 -> 2697048.1 | P5: ='P11'!$B277 -> 1100013.8 | Q5: ='P12'!$B277 -> 1347907.5 | R5: ='P13'!$B277 -> 3731054.9 | S5: ='P14'!$B277 -> 3795013.3 | T5: ='P15'!$B277 -> 1383625 | U5: ='P16'!$B277 -> 701096.28 | V5: ='P17'!$B277 -> 1270537.3 | W5: ='P18'!$B277 -> 2233533.8 | X5: ='P19'!$B277 -> 2813762.4 | Y5: ='P20'!$B277 -> 3324607.3 | Z5: ='P21'!B277 -> 3412631.1 | AA5: ='P22'!B277 -> 3502786.3 | AB5: ='P23'!B277 -> 5875234.7 | AC5: ='P24'!B277 -> 4898099.3 | AD5: ='P25'!B277 -> 4526014.8 | AE5: ='P26'!B277 -> 4651543.6 | AF5: ='P27'!B277 -> 3269427.8 | AG5: ='P28'!B277 -> 1546151.7 | AH5: ='P29'!B277 -> -2452371.4 | AI5: ='P30'!B277 -> -350869.11 | AJ5: ='P31'!B277 -> 1010287.2 | AK5: ='P32'!$B277 -> 1121033 | AL5: ='P33'!$B277 -> -978698.69 | AM5: ='P34'!$B277 -> 1297904.4 | AN5: ='P35'!$B277 -> 696793.33 | AO5: ='P36'!$B277 -> 1099085.1 | AP5: ='P37'!$B277 -> 2773467.4 | AQ5: ='P38'!$B277 -> 3112031.7 | AR5: ='P39'!$B277 -> 3352244.6 | AS5: ='P40'!$B277 -> 3449804.6 | AT5: ='P41'!$B277 -> 3810124 | AU5: ='P42'!$B277 -> 3952447.2 | AV5: ='P43'!$B277 -> 4306082.8 | AW5: ='P44'!$B277 -> 4664647 | AX5: ='P45'!$B277 -> 4429175.9 | AY5: ='P46'!$B277 -> 4452192.9 | AZ5: ='P47'!$B277 -> 5232546.9 | BA5: ='P48'!$B277 -> 5061030.7 | BB5: ='P49'!$B277 -> 4292259.1 | BC5: ='P50'!$B277 -> 3793014.5 | BD5: ='P51'!$B277 -> 3155181 | BE5: ='P52'!$B277 -> 4761233.1 | BF5: ='P53'!$B277 -> 3437087.1 | BG5: ='P54'!$B277 -> 3728824.1 | BH5: ='P55'!$B277 -> 3963170.5 | BI5: ='P56'!$B277 -> 4113013.3 | BJ5: ='P57'!$B277 -> 4353060.3 | BK5: ='P58'!$B277 -> 4365110.3 | BL5: ='P59'!$B277 -> 4365357.9 | BM5: ='P60'!$B277 -> 4337658.4 | BN5: ='P61'!$B277 -> 3708282.7 | BO5: ='P62'!$B277 -> 3551343.4 | BP5: ='P63'!$B277 -> 0 | BQ5: ='P64'!$B277 -> 0 | BR5: ='P65'!$B277 -> 0 | BS5: ='P66'!$B277 -> 0 | BT5: ='P67'!$B277 -> 0 | BU5: ='P68'!$B277 -> 0 | BV5: ='P69'!$B277 -> 0 | BW5: ='P70'!$B277 -> 0 | BX5: ='P71'!$B277 -> 0 | BY5: ='P72'!$B277 -> 0 | BZ5: ='P73'!$B277 -> 0 | CA5: ='P74'!$B277 -> 0 | CB5: ='P75'!$B277 -> 0
A6: Add back non-cash expenses | E6: Debt/Equity Ratio | F6: ='P1'!B278 -> 0.28523738 | G6: ='P2'!$B278 -> 0.25769477 | H6: ='P3'!$B278 -> 0.23912567 | I6: ='P4'!$B278 -> 0.30500633 | J6: ='P5'!$B278 -> 0.26965442 | K6: ='P6'!$B278 -> 0.29056062 | L6: ='P7'!$B278 -> 0.73072479 | M6: ='P8'!$B278 -> 0.7507871 | N6: ='P9'!$B278 -> 0.78594769 | O6: ='P10'!$B278 -> 0.79153046 | P6: ='P11'!$B278 -> 0.86317616 | Q6: ='P12'!$B278 -> 0.93671189 | R6: ='P13'!$B278 -> 0.89510392 | S6: ='P14'!$B278 -> 0.77940219 | T6: ='P15'!$B278 -> 0.76020079 | U6: ='P16'!$B278 -> 0.76436085 | V6: ='P17'!$B278 -> 0.753345 | W6: ='P18'!$B278 -> 0.71719797 | X6: ='P19'!$B278 -> 0.74822674 | Y6: ='P20'!$B278 -> 0.76714946 | Z6: ='P21'!B278 -> 0.78362297 | AA6: ='P22'!B278 -> 0.79867043 | AB6: ='P23'!B278 -> 0.74712746 | AC6: ='P24'!B278 -> 0.72633268 | AD6: ='P25'!B278 -> 0.71515716 | AE6: ='P26'!B278 -> 0.70324352 | AF6: ='P27'!B278 -> 0.72197109 | AG6: ='P28'!B278 -> 0.71312994 | AH6: ='P29'!B278 -> 0.77050169 | AI6: ='P30'!B278 -> 0.79969996 | AJ6: ='P31'!B278 -> 0.80226053 | AK6: ='P32'!B278 -> 0.80494791 | AL6: ='P33'!$B278 -> 1.5812271 | AM6: ='P34'!$B278 -> 1.5741336 | AN6: ='P35'!$B278 -> 1.6215352 | AO6: ='P36'!$B278 -> 1.6859546 | AP6: ='P37'!$B278 -> 1.6073071 | AQ6: ='P38'!$B278 -> 1.6630499 | AR6: ='P39'!$B278 -> 1.564016 | AS6: ='P40'!$B278 -> 1.6468 | AT6: ='P41'!$B278 -> 1.6013117 | AU6: ='P42'!$B278 -> 1.6175234 | AV6: ='P43'!$B278 -> 1.6095794 | AW6: ='P44'!$B278 -> 1.5823867 | AX6: ='P45'!$B278 -> 1.5312649 | AY6: ='P46'!$B278 -> 1.4866414 | AZ6: ='P47'!$B278 -> 1.4059626 | BA6: ='P48'!$B278 -> 1.1748519 | BB6: ='P49'!$B278 -> 1.2440895 | BC6: ='P50'!$B278 -> 1.2398398 | BD6: ='P51'!$B278 -> 1.2623033 | BE6: ='P52'!$B278 -> 1.4701597 | BF6: ='P53'!$B278 -> 1.5394597 | BG6: ='P54'!$B278 -> 1.5967007 | BH6: ='P55'!$B278 -> 1.6403514 | BI6: ='P56'!$B278 -> 1.862077 | BJ6: ='P57'!$B278 -> 1.744002 | BK6: ='P58'!$B278 -> 1.8055285 | BL6: ='P59'!$B278 -> 1.816945 | BM6: ='P60'!$B278 -> 1.882829 | BN6: ='P61'!$B278 -> 1.7090574 | BO6: ='P62'!$B278 -> 1.1179938 | BP6: ='P63'!$B278 -> 0 | BQ6: ='P64'!$B278 -> 0 | BR6: ='P65'!$B278 -> 0 | BS6: ='P66'!$B278 -> 0 | BT6: ='P67'!$B278 -> 0 | BU6: ='P68'!$B278 -> 0 | BV6: ='P69'!$B278 -> 0 | BW6: ='P70'!$B278 -> 0 | BX6: ='P71'!$B278 -> 0 | BY6: ='P72'!$B278 -> 0 | BZ6: ='P73'!$B278 -> 0 | CA6: ='P74'!$B278 -> 0 | CB6: ='P75'!$B278 -> 0
A7: Depreciation part of transportation expense | C7: =ACTIVE!B207 -> 170498 | E7: Debt /(Debt + Equity) | F7: ='P1'!B279 -> 0.22193362 | G7: ='P2'!$B279 -> 0.20489452 | H7: ='P3'!$B279 -> 0.19297935 | I7: ='P4'!$B279 -> 0.23372019 | J7: ='P5'!$B279 -> 0.2123841 | K7: ='P6'!$B279 -> 0.22514295 | L7: ='P7'!$B279 -> 0.42220739 | M7: ='P8'!$B279 -> 0.42882832 | N7: ='P9'!$B279 -> 0.44007319 | O7: ='P10'!$B279 -> 0.44181803 | P7: ='P11'!$B279 -> 0.4632821 | Q7: ='P12'!$B279 -> 0.48366094 | R7: ='P13'!$B279 -> 0.47232445 | S7: ='P14'!$B279 -> 0.43801351 | T7: ='P15'!$B279 -> 0.431883 | U7: ='P16'!$B279 -> 0.43322252 | V7: ='P17'!$B279 -> 0.42966159 | W7: ='P18'!$B279 -> 0.41765596 | X7: ='P19'!$B279 -> 0.42799182 | Y7: ='P20'!$B279 -> 0.43411691 | Z7: ='P21'!B279 -> 0.43934339 | AA7: ='P22'!B279 -> 0.44403378 | AB7: ='P23'!B279 -> 0.42763192 | AC7: ='P24'!B279 -> 0.42073738 | AD7: ='P25'!B279 -> 0.41696305 | AE7: ='P26'!B279 -> 0.41288489 | AF7: ='P27'!B279 -> 0.41927016 | AG7: ='P28'!B279 -> 0.41627312 | AH7: ='P29'!B279 -> 0.43518834 | AI7: ='P30'!B279 -> 0.44435182 | AJ7: ='P31'!B279 -> 0.44514126 | AK7: ='P32'!B279 -> 0.44596739 | AL7: ='P33'!$B279 -> 0.61258736 | AM7: ='P34'!$B279 -> 0.61151978 | AN7: ='P35'!$B279 -> 0.61854413 | AO7: ='P36'!$B279 -> 0.62769289 | AP7: ='P37'!$B279 -> 0.61646251 | AQ7: ='P38'!$B279 -> 0.6244907 | AR7: ='P39'!$B279 -> 0.60998684 | AS7: ='P40'!$B279 -> 0.62218528 | AT7: ='P41'!$B279 -> 0.61557856 | AU7: ='P42'!$B279 -> 0.61795949 | AV7: ='P43'!$B279 -> 0.61679648 | AW7: ='P44'!$B279 -> 0.61276132 | AX7: ='P45'!$B279 -> 0.6049406 | AY7: ='P46'!$B279 -> 0.59785115 | AZ7: ='P47'!$B279 -> 0.58436594 | BA7: ='P48'!$B279 -> 0.54019857 | BB7: ='P49'!$B279 -> 0.55438498 | BC7: ='P50'!$B279 -> 0.5535395 | BD7: ='P51'!$B279 -> 0.55797262 | BE7: ='P52'!$B279 -> 0.59516787 | BF7: ='P53'!$B279 -> 0.60621544 | BG7: ='P54'!$B279 -> 0.61489593 | BH7: ='P55'!$B279 -> 0.62126253 | BI7: ='P56'!$B279 -> 0.65060339 | BJ7: ='P57'!$B279 -> 0.63556878 | BK7: ='P58'!$B279 -> 0.64356092 | BL7: ='P59'!$B279 -> 0.64500549 | BM7: ='P60'!$B279 -> 0.65311852 | BN7: ='P61'!$B279 -> 0.63086792 | BO7: ='P62'!$B279 -> 0.52785509 | BP7: ='P63'!$B279 -> 0 | BQ7: ='P64'!$B279 -> 0 | BR7: ='P65'!$B279 -> 0 | BS7: ='P66'!$B279 -> 0 | BT7: ='P67'!$B279 -> 0 | BU7: ='P68'!$B279 -> 0 | BV7: ='P69'!$B279 -> 0 | BW7: ='P70'!$B279 -> 0 | BX7: ='P71'!$B279 -> 0 | BY7: ='P72'!$B279 -> 0 | BZ7: ='P73'!$B279 -> 0 | CA7: ='P74'!$B279 -> 0 | CB7: ='P75'!$B279 -> 0
A8: Interest expense | C8: =ACTIVE!B222 -> 815763 | E8: Equity/(Debt+Equity) | F8: ='P1'!B280 -> 0.77806638 | G8: ='P2'!$B280 -> 0.79510548 | H8: ='P3'!$B280 -> 0.80702065 | I8: ='P4'!$B280 -> 0.76627981 | J8: ='P5'!$B280 -> 0.7876159 | K8: ='P6'!$B280 -> 0.77485705 | L8: ='P7'!$B280 -> 0.57779261 | M8: ='P8'!$B280 -> 0.57117168 | N8: ='P9'!$B280 -> 0.55992681 | O8: ='P10'!$B280 -> 0.55818197 | P8: ='P11'!$B280 -> 0.5367179 | Q8: ='P12'!$B280 -> 0.51633906 | R8: ='P13'!$B280 -> 0.52767555 | S8: ='P14'!$B280 -> 0.56198649 | T8: ='P15'!$B280 -> 0.568117 | U8: ='P16'!$B280 -> 0.56677748 | V8: ='P17'!$B280 -> 0.57033841 | W8: ='P18'!$B280 -> 0.58234404 | X8: ='P19'!$B280 -> 0.57200818 | Y8: ='P20'!$B280 -> 0.56588309 | Z8: ='P21'!B280 -> 0.56065661 | AA8: ='P22'!B280 -> 0.55596622 | AB8: ='P23'!B280 -> 0.57236808 | AC8: ='P24'!B280 -> 0.57926262 | AD8: ='P25'!B280 -> 0.58303695 | AE8: ='P26'!B280 -> 0.58711511 | AF8: ='P27'!B280 -> 0.58072984 | AG8: ='P28'!B280 -> 0.58372688 | AH8: ='P29'!B280 -> 0.56481166 | AI8: ='P30'!B280 -> 0.55564818 | AJ8: ='P31'!B280 -> 0.55485874 | AK8: ='P32'!B280 -> 0.55403261 | AL8: ='P33'!$B280 -> 0.38741264 | AM8: ='P34'!$B280 -> 0.38848022 | AN8: ='P35'!$B280 -> 0.38145587 | AO8: ='P36'!$B280 -> 0.37230711 | AP8: ='P37'!$B280 -> 0.38353749 | AQ8: ='P38'!$B280 -> 0.3755093 | AR8: ='P39'!$B280 -> 0.39001316 | AS8: ='P40'!$B280 -> 0.37781472 | AT8: ='P41'!$B280 -> 0.38442144 | AU8: ='P42'!$B280 -> 0.38204051 | AV8: ='P43'!$B280 -> 0.38320352 | AW8: ='P44'!$B280 -> 0.38723868 | AX8: ='P45'!$B280 -> 0.3950594 | AY8: ='P46'!$B280 -> 0.40214885 | AZ8: ='P47'!$B280 -> 0.41563406 | BA8: ='P48'!$B280 -> 0.45980143 | BB8: ='P49'!$B280 -> 0.44561502 | BC8: ='P50'!$B280 -> 0.4464605 | BD8: ='P51'!$B280 -> 0.44202738 | BE8: ='P52'!$B280 -> 0.40483213 | BF8: ='P53'!$B280 -> 0.39378456 | BG8: ='P54'!$B280 -> 0.38510407 | BH8: ='P55'!$B280 -> 0.37873747 | BI8: ='P56'!$B280 -> 0.34939661 | BJ8: ='P57'!$B280 -> 0.36443122 | BK8: ='P58'!$B280 -> 0.35643908 | BL8: ='P59'!$B280 -> 0.35499451 | BM8: ='P60'!$B280 -> 0.34688148 | BN8: ='P61'!$B280 -> 0.36913208 | BO8: ='P62'!$B280 -> 0.47214491 | BP8: ='P63'!$B280 -> 0 | BQ8: ='P64'!$B280 -> 0 | BR8: ='P65'!$B280 -> 0 | BS8: ='P66'!$B280 -> 0 | BT8: ='P67'!$B280 -> 0 | BU8: ='P68'!$B280 -> 0 | BV8: ='P69'!$B280 -> 0 | BW8: ='P70'!$B280 -> 0 | BX8: ='P71'!$B280 -> 0 | BY8: ='P72'!$B280 -> 0 | BZ8: ='P73'!$B280 -> 0 | CA8: ='P74'!$B280 -> 0 | CB8: ='P75'!$B280 -> 0
A9: Factory Depreciation | C9: =ACTIVE!B223 -> 190596 | E9: Expected Return on Debt | F9: ='P1'!B281 -> 0.05016 | G9: ='P2'!$B281 -> 0.05016 | H9: ='P3'!$B281 -> 0.05016 | I9: ='P4'!$B281 -> 0.05016 | J9: ='P5'!$B281 -> 0.05016 | K9: ='P6'!$B281 -> 0.05016 | L9: ='P7'!$B281 -> 0.060192 | M9: ='P8'!$B281 -> 0.060192 | N9: ='P9'!$B281 -> 0.060192 | O9: ='P10'!$B281 -> 0.060192 | P9: ='P11'!$B281 -> 0.065208 | Q9: ='P12'!$B281 -> 0.065208 | R9: ='P13'!$B281 -> 0.065208 | S9: ='P14'!$B281 -> 0.060192 | T9: ='P15'!$B281 -> 0.060192 | U9: ='P16'!$B281 -> 0.060192 | V9: ='P17'!$B281 -> 0.060192 | W9: ='P18'!$B281 -> 0.060192 | X9: ='P19'!$B281 -> 0.060192 | Y9: ='P20'!$B281 -> 0.060192 | Z9: ='P21'!B281 -> 0.060192 | AA9: ='P22'!B281 -> 0.060192 | AB9: ='P23'!B281 -> 0.060192 | AC9: ='P24'!B281 -> 0.060192 | AD9: ='P25'!B281 -> 0.060192 | AE9: ='P26'!B281 -> 0.060192 | AF9: ='P27'!B281 -> 0.060192 | AG9: ='P28'!B281 -> 0.060192 | AH9: ='P29'!B281 -> 0.060192 | AI9: ='P30'!B281 -> 0.060192 | AJ9: ='P31'!B281 -> 0.065208 | AK9: ='P32'!B281 -> 0.065208 | AL9: ='P33'!$B281 -> 0.070224 | AM9: ='P34'!$B281 -> 0.070224 | AN9: ='P35'!$B281 -> 0.10032 | AO9: ='P36'!$B281 -> 0.10032 | AP9: ='P37'!$B281 -> 0.10032 | AQ9: ='P38'!$B281 -> 0.10032 | AR9: ='P39'!$B281 -> 0.070224 | AS9: ='P40'!$B281 -> 0.10032 | AT9: ='P41'!$B281 -> 0.10032 | AU9: ='P42'!$B281 -> 0.10032 | AV9: ='P43'!$B281 -> 0.10032 | AW9: ='P44'!$B281 -> 0.070224 | AX9: ='P45'!$B281 -> 0.070224 | AY9: ='P46'!$B281 -> 0.070224 | AZ9: ='P47'!$B281 -> 0.070224 | BA9: ='P48'!$B281 -> 0.065208 | BB9: ='P49'!$B281 -> 0.070224 | BC9: ='P50'!$B281 -> 0.070224 | BD9: ='P51'!$B281 -> 0.070224 | BE9: ='P52'!$B281 -> 0.070224 | BF9: ='P53'!$B281 -> 0.070224 | BG9: ='P54'!$B281 -> 0.070224 | BH9: ='P55'!$B281 -> 0.10032 | BI9: ='P56'!$B281 -> 0.10032 | BJ9: ='P57'!$B281 -> 0.10032 | BK9: ='P58'!$B281 -> 0.10032 | BL9: ='P59'!$B281 -> 0.10032 | BM9: ='P60'!$B281 -> 0.10032 | BN9: ='P61'!$B281 -> 0.10032 | BO9: ='P62'!$B281 -> 0.065208 | BP9: ='P63'!$B281 -> 0 | BQ9: ='P64'!$B281 -> 0 | BR9: ='P65'!$B281 -> 0 | BS9: ='P66'!$B281 -> 0 | BT9: ='P67'!$B281 -> 0 | BU9: ='P68'!$B281 -> 0 | BV9: ='P69'!$B281 -> 0 | BW9: ='P70'!$B281 -> 0 | BX9: ='P71'!$B281 -> 0 | BY9: ='P72'!$B281 -> 0 | BZ9: ='P73'!$B281 -> 0 | CA9: ='P74'!$B281 -> 0 | CB9: ='P75'!$B281 -> 0
